Workbook

Sheet IC 2024
K4: 0.05
K6: Meetings
B7: Nome | C7: Inicio | D7: Data | E7: Saída | F7: Manager | G7: Monthly Fee | H7: Success Fee | I7: Project Month | J7: Status | K7: Comments | L7: jan/24 | M7: fev/24 | N7: mar/24 | O7: abr/24 | P7: mai/24 | Q7: jun/24 | R7: jul/24 | S7: ago/24 | T7: set/24 | U7: out/24 | V7: nov/24 | W7: dez/24 | X7: Total
B8: Jossois | C8: 45597 | D8: 21 de novembro | F8: Isabela | G8: 1200 | H8: - | I8: 1 | J8: Active
B9: Grow Out | C9: 45627 | D9: 1 de dezembro | F9: Allen | G9: 1400 | H9: - | I9: 1 | J9: active | K9: começa em dezembro
B10: Tecnho store | C10: 45444 | D10: 20 de junho | F10: Allen | G10: 1500 | H10: 0.05 | I10: 1 | J10: Active
B11: Irmãos Rodrigues | C11: 45536 | D11: 23 de setembro | F11: Sérgio | G11: 1200 | H11: - | I11: 1 | J11: active
B12: Fapil | C12: 45536 | D12: 13 de set | F12: Sérgio | G12: 1500 | H12: - | I12: 2 | J12: Active
B13: Infinite Foundry | C13: 45536 | D13: 8 de setembro | F13: Marco | G13: 1900 | H13: - | I13: 0 | J13: Active | S13: 0 | X13: =Tabela1[[#This Row],[jan/24]]+Tabela1[[#This Row],[fev/24]]+Tabela1[[#This Row],[mar/24]]+Tabela1[[#This Row],[abr/24]]+Tabela1[[#This Row],[mai/24]]+Tabela1[[#This Row],[jun/24]]+Tabela1[[#This Row],[jul/24]]+Tabela1[[#This Row],[ago/24]]+Tabela1[[#This Row],[set/24]]+Tabela1[[#This Row],[out/24]]+Tabela1[[#This Row],[nov/24]]+Tabela1[[#This Row],[dez/24]] -> 0
B14: Delta | C14: 45444 | D14: 1 de junho | F14: Marco | G14: 1100 | H14: - | I14: 1 | J14: Active | K14: acaba dia 31 de Janiero | Q14: 0 | R14: 2 | S14: 1 | X14: =Tabela1[[#This Row],[jan/24]]+Tabela1[[#This Row],[fev/24]]+Tabela1[[#This Row],[mar/24]]+Tabela1[[#This Row],[abr/24]]+Tabela1[[#This Row],[mai/24]]+Tabela1[[#This Row],[jun/24]]+Tabela1[[#This Row],[jul/24]]+Tabela1[[#This Row],[ago/24]]+Tabela1[[#This Row],[set/24]]+Tabela1[[#This Row],[out/24]]+Tabela1[[#This Row],[nov/24]]+Tabela1[[#This Row],[dez/24]] -> 3
B15: Givachoice | C15: 45444 | D15: 27 de junho | F15: Isabela | G15: 1300 | H15: - | I15: 2 | J15: Active | Q15: 1 | R15: 2 | S15: 0 | T15: 2 | X15: =Tabela1[[#This Row],[jan/24]]+Tabela1[[#This Row],[fev/24]]+Tabela1[[#This Row],[mar/24]]+Tabela1[[#This Row],[abr/24]]+Tabela1[[#This Row],[mai/24]]+Tabela1[[#This Row],[jun/24]]+Tabela1[[#This Row],[jul/24]]+Tabela1[[#This Row],[ago/24]]+Tabela1[[#This Row],[set/24]]+Tabela1[[#This Row],[out/24]]+Tabela1[[#This Row],[nov/24]]+Tabela1[[#This Row],[dez/24]] -> 5
B16: Vittawood | C16: 45292 | D16: 8 de janeiro | F16: Marco | G16: 1100 | H16: - | I16: 7 | J16: Active | L16: 1 | M16: 3 | N16: 3 | O16: 2 | P16: 4 | Q16: 4 | R16: 3 | S16: 1 | X16: =Tabela1[[#This Row],[jan/24]]+Tabela1[[#This Row],[fev/24]]+Tabela1[[#This Row],[mar/24]]+Tabela1[[#This Row],[abr/24]]+Tabela1[[#This Row],[mai/24]]+Tabela1[[#This Row],[jun/24]]+Tabela1[[#This Row],[jul/24]]+Tabela1[[#This Row],[ago/24]]+Tabela1[[#This Row],[set/24]]+Tabela1[[#This Row],[out/24]]+Tabela1[[#This Row],[nov/24]]+Tabela1[[#This Row],[dez/24]] -> 21
B17: FJMPC | C17: 45323 | D17: 28 de fev | F17: Marco | G17: 1500 | H17: - | I17: 6 | J17: Active | M17: 2 | N17: 2 | O17: 3 | P17: 4 | Q17: 2 | R17: 1 | S17: 0 | X17: =Tabela1[[#This Row],[jan/24]]+Tabela1[[#This Row],[fev/24]]+Tabela1[[#This Row],[mar/24]]+Tabela1[[#This Row],[abr/24]]+Tabela1[[#This Row],[mai/24]]+Tabela1[[#This Row],[jun/24]]+Tabela1[[#This Row],[jul/24]]+Tabela1[[#This Row],[ago/24]]+Tabela1[[#This Row],[set/24]]+Tabela1[[#This Row],[out/24]]+Tabela1[[#This Row],[nov/24]]+Tabela1[[#This Row],[dez/24]] -> 14
B18: Ramagplast | C18: 45658 | D18: 8 de janeiro | F18: Sérgio | G18: 1000 | I18: 1 | J18: active | K18: começa em janeiro
B19: Alpine Seafood | C19: 45559 | D19: - | F19: Allen | G19: 1200 | H19: - | I19: 1 | J19: Active | S19: 0
B20: Artnovion | C20: 45559 | D20: - | F20: Marco | G20: 1200 | H20: - | I20: 1 | J20: Active | S20: 0
B21: Cyberx | C21: 45627 | D21: 45627 | F21: Marco | G21: 1900 | H21: - | I21: 1 | J21: Active
B22: SF Globallaser | C22: 45627 | D22: 16 de Dezembro | F22: Sérgio | G22: 1900 | H22: 0.03
B23: Exposerve | C23: 45658 | D23: 2 de janeiro | F23: Sérgio | G23: 1500 | I23: 3 | J23: active | K23: reunião de alinhamento em dez mas começa em janeiro
B24: Plasvip | C24: 45658 | D24: 7 de Janeiro | F24: Sergio | G24: 1900 | H24: 0.05 | I24: 1 | J24: active
B25: Recheio | C25: 45292 | D25: 1 de janeiro | F25: Marco | G25: 1100 | H25: - | I25: 3 | J25: active | L25: 4 | M25: 3 | N25: 2 | O25: 1 | P25: 2 | Q25: 3 | R25: 2 | S25: 0 | X25: =Tabela1[[#This Row],[jan/24]]+Tabela1[[#This Row],[fev/24]]+Tabela1[[#This Row],[mar/24]]+Tabela1[[#This Row],[abr/24]]+Tabela1[[#This Row],[mai/24]]+Tabela1[[#This Row],[jun/24]]+Tabela1[[#This Row],[jul/24]]+Tabela1[[#This Row],[ago/24]]+Tabela1[[#This Row],[set/24]]+Tabela1[[#This Row],[out/24]]+Tabela1[[#This Row],[nov/24]]+Tabela1[[#This Row],[dez/24]] -> 17
B26: Caixa Mágica | C26: 45658 | D26: 20 de janeiro | F26: Marco | G26: 1900 | H26: 0.05 | I26: 12 | J26: active
B27: José Luis Madeiras | C27: 45597 | D27: 20 de novembro | F27: Sérgio | G27: 1500 | H27: - | I27: 1 | J27: hold
B29: Farvoli | C29: 45444 | D29: 45454 | E29: 45962 | F29: Marco | G29: 1500 | H29: - | I29: 2 | J29: hold | Q29: 0 | R29: 4 | S29: 0 | X29: =Tabela1[[#This Row],[jan/24]]+Tabela1[[#This Row],[fev/24]]+Tabela1[[#This Row],[mar/24]]+Tabela1[[#This Row],[abr/24]]+Tabela1[[#This Row],[mai/24]]+Tabela1[[#This Row],[jun/24]]+Tabela1[[#This Row],[jul/24]]+Tabela1[[#This Row],[ago/24]]+Tabela1[[#This Row],[set/24]]+Tabela1[[#This Row],[out/24]]+Tabela1[[#This Row],[nov/24]]+Tabela1[[#This Row],[dez/24]] -> 4
B30: Arxi | C30: 45559 | D30: 45537 | E30: 45567 | F30: Marco | G30: 1500 | H30: - | I30: 1 | J30: hold | S30: 0
B31: Atelier Sabiina Design | C31: dec/2024 | D31: 45627 | E31: 45627 | F31: Sérgio | G31: 1500 | I31: 1 | J31: hold | K31: começa em dezembro
B32: GinT | C32: 45474 | D32: 45482 | E32: 45544 | F32: Allen | G32: 1500 | H32: - | I32: 3 | J32: hold | K32: estamos à espera do pagamento para continuar | R32: 2 | S32: 1 | T32: 3 | U32: 1 | X32: =Tabela1[[#This Row],[jan/24]]+Tabela1[[#This Row],[fev/24]]+Tabela1[[#This Row],[mar/24]]+Tabela1[[#This Row],[abr/24]]+Tabela1[[#This Row],[mai/24]]+Tabela1[[#This Row],[jun/24]]+Tabela1[[#This Row],[jul/24]]+Tabela1[[#This Row],[ago/24]]+Tabela1[[#This Row],[set/24]]+Tabela1[[#This Row],[out/24]]+Tabela1[[#This Row],[nov/24]]+Tabela1[[#This Row],[dez/24]] -> 7
B33: Mariano | C33: 45505 | D33: 45505 | E33: 45413 | F33: Isabela | G33: 800 | I33: 0 | J33: hold | K33: quer renovar, ainda n deu data | L33: 2 | M33: 1 | N33: 0 | O33: 0 | P33: 0 | Q33: 0 | R33: 0 | S33: 0 | X33: =Tabela1[[#This Row],[jan/24]]+Tabela1[[#This Row],[fev/24]]+Tabela1[[#This Row],[mar/24]]+Tabela1[[#This Row],[abr/24]]+Tabela1[[#This Row],[mai/24]]+Tabela1[[#This Row],[jun/24]]+Tabela1[[#This Row],[jul/24]]+Tabela1[[#This Row],[ago/24]]+Tabela1[[#This Row],[set/24]]+Tabela1[[#This Row],[out/24]]+Tabela1[[#This Row],[nov/24]]+Tabela1[[#This Row],[dez/24]] -> 3
B34: Artemola | C34: 45078 | D34: 45544 | E34: 45544 | F34: Allen | G34: 1100 | I34: 15 | J34: hold | K34: volta em fevereiro | L34: 3 | M34: 2 | N34: 1 | O34: 2 | P34: 0 | Q34: 0 | R34: 2 | S34: 0 | T34: 1 | U34: 1 | X34: =Tabela1[[#This Row],[jan/24]]+Tabela1[[#This Row],[fev/24]]+Tabela1[[#This Row],[mar/24]]+Tabela1[[#This Row],[abr/24]]+Tabela1[[#This Row],[mai/24]]+Tabela1[[#This Row],[jun/24]]+Tabela1[[#This Row],[jul/24]]+Tabela1[[#This Row],[ago/24]]+Tabela1[[#This Row],[set/24]]+Tabela1[[#This Row],[out/24]]+Tabela1[[#This Row],[nov/24]]+Tabela1[[#This Row],[dez/24]] -> 12
B36: Crafil | C36: 45444 | D36: 45450 | E36: 45598 | F36: Isabela | G36: 1500 | H36: - | I36: 1 | J36: Finished | Q36: 0 | R36: 5 | S36: 1 | X36: =Tabela1[[#This Row],[jan/24]]+Tabela1[[#This Row],[fev/24]]+Tabela1[[#This Row],[mar/24]]+Tabela1[[#This Row],[abr/24]]+Tabela1[[#This Row],[mai/24]]+Tabela1[[#This Row],[jun/24]]+Tabela1[[#This Row],[jul/24]]+Tabela1[[#This Row],[ago/24]]+Tabela1[[#This Row],[set/24]]+Tabela1[[#This Row],[out/24]]+Tabela1[[#This Row],[nov/24]]+Tabela1[[#This Row],[dez/24]] -> 6
B37: Creative Textile | C37: 45566 | D37: 45581 | E37: 45629 | F37: Isabela | G37: 1500 | H37: - | I37: 1 | J37: Finished
B38: Socutel | C38: 45566 | D38: 45587 | E38: 45656 | F38: Sérgio | G38: 1500 | H38: - | I38: 1 | J38: Finished
B39: Cubo Hotel | C39: 45597 | D39: 45623 | E39: 45656 | F39: Allen | G39: 1500 | H39: - | I39: 1 | J39: Finished | K39: começa dia 27 de dezembro
B40: Granidense | C40: 45444 | D40: 45445 | E40: 45623 | F40: Marco | G40: 1900 | H40: - | I40: 1 | J40: Finished | Q40: 0 | R40: 1 | S40: 2 | X40: =Tabela1[[#This Row],[jan/24]]+Tabela1[[#This Row],[fev/24]]+Tabela1[[#This Row],[mar/24]]+Tabela1[[#This Row],[abr/24]]+Tabela1[[#This Row],[mai/24]]+Tabela1[[#This Row],[jun/24]]+Tabela1[[#This Row],[jul/24]]+Tabela1[[#This Row],[ago/24]]+Tabela1[[#This Row],[set/24]]+Tabela1[[#This Row],[out/24]]+Tabela1[[#This Row],[nov/24]]+Tabela1[[#This Row],[dez/24]] -> 3
B41: Cubu Fitness | C41: 45536 | D41: 45539 | E41: 45625 | F41: Isabela | G41: 1200 | H41: - | I41: 0 | J41: Finished | T41: 1
B42: ANC Brands | C42: 45474 | D42: 45492 | E42: 45624 | F42: Sérgio | G42: 1500 | H42: - | I42: 1 | J42: Finished | R42: 2 | S42: 0 | X42: =Tabela1[[#This Row],[jan/24]]+Tabela1[[#This Row],[fev/24]]+Tabela1[[#This Row],[mar/24]]+Tabela1[[#This Row],[abr/24]]+Tabela1[[#This Row],[mai/24]]+Tabela1[[#This Row],[jun/24]]+Tabela1[[#This Row],[jul/24]]+Tabela1[[#This Row],[ago/24]]+Tabela1[[#This Row],[set/24]]+Tabela1[[#This Row],[out/24]]+Tabela1[[#This Row],[nov/24]]+Tabela1[[#This Row],[dez/24]] -> 2
B43: Freire Lobo | C43: 45566 | D43: 45581 | E43: 45612 | F43: Allen | G43: 1500 | H43: - | I43: 2 | J43: Finished
B44: Lambda Golf | C44: 45231 | F44: Bruno | G44: 1100 | I44: 3 | J44: Finished | L44: 2 | M44: 1 | N44: 0 | O44: 0 | P44: 0 | Q44: 0 | R44: 0 | S44: 0 | X44: 2
B45: VOLT | C45: 45200 | F45: Andres | G45: 600 | I45: 2 | J45: Finished | L45: 0 | M45: 0 | N45: 0 | O45: 0 | P45: 0 | Q45: 0 | R45: 0 | S45: 0 | X45: 2
B46: VECO | C46: 45078 | F46: Bruno | G46: 1100 | I46: 6 | J46: Finished | L46: 0 | M46: 0 | N46: 0 | O46: 0 | P46: 0 | Q46: 0 | R46: 0 | S46: 0 | X46: 3
...

Sheet IC 2025
L4: 0.05
L6: Meetings
B7: Nome | C7: Inicio | D7: Data entrada | E7: Data 2 | F7: Meses | G7: Manager | H7: Monthly Fee | I7: Success Fee | J7: Project Month | K7: Status | L7: Comments | M7: jan/24 | N7: fev/24 | O7: mar/24 | P7: abr/24 | Q7: mai/24 | R7: jun/24 | S7: jul/24 | T7: ago/24 | U7: set/24 | V7: out/24 | W7: nov/24 | X7: dez/24 | Y7: Total
B8: Grow Out | C8: 2024 Dezembro | D8: 45627 | E8: =TODAY() -> 46171 | F8: =DATEDIF(Tabela153[[#This Row],[Data entrada]],Tabela153[[#This Row],[Data 2]], "M") -> 17 | G8: Allen | H8: 1400 | I8: - | J8: 1 | K8: Active
B9: Delta | C9: 2025 Junho | D9: 45444 | E9: =TODAY() -> 46171 | F9: =DATEDIF(Tabela153[[#This Row],[Data entrada]],Tabela153[[#This Row],[Data 2]], "M") -> 23 | G9: Marco | H9: 1100 | I9: - | J9: 1 | K9: Active
B10: FJMPC | C10: 2024 Fevereiro | D10: 45350 | E10: =TODAY() -> 46171 | F10: =DATEDIF(Tabela153[[#This Row],[Data entrada]],Tabela153[[#This Row],[Data 2]], "M") -> 27 | G10: Marco | H10: 1500 | I10: - | J10: 6 | K10: Active
B11: Alpine Seafood | C11: 2024 Setembro | D11: 45536 | E11: =TODAY() -> 46171 | G11: Allen | H11: 1200 | I11: - | J11: 1 | K11: Active
B12: Artnovion | C12: 2024 Setembro | D12: 45536 | E12: =TODAY() -> 46171 | G12: Manel | H12: 1200 | I12: - | J12: 1 | K12: Active
B13: Plasvip | C13: 2025 Janeiro | D13: 45664 | E13: =TODAY() -> 46171 | F13: =DATEDIF(Tabela153[[#This Row],[Data entrada]],Tabela153[[#This Row],[Data 2]], "M") -> 16 | G13: Sérgio | H13: 1900 | I13: 0.05 | J13: 1 | K13: Active
B14: Recheio | C14: 2024 Janeiro | D14: 45292 | E14: =TODAY() -> 46171 | F14: =DATEDIF(Tabela153[[#This Row],[Data entrada]],Tabela153[[#This Row],[Data 2]], "M") -> 28 | G14: Marco | H14: 1100 | I14: - | J14: 3 | K14: Active
B15: Caixa Mágica | C15: 2025 Janeiro | D15: 45677 | E15: =TODAY() -> 46171 | F15: =DATEDIF(Tabela153[[#This Row],[Data entrada]],Tabela153[[#This Row],[Data 2]], "M") -> 16 | G15: Marco | H15: 1900 | I15: 0.05 | J15: 12 | K15: Active
B16: Aquecinox | C16: 2025 Fevereiro | D16: 45694 | E16: =TODAY() -> 46171 | F16: =DATEDIF(Tabela153[[#This Row],[Data entrada]],Tabela153[[#This Row],[Data 2]], "M") -> 15 | G16: Manel | H16: 1500 | K16: Active
B17: Core Concept | C17: 2025 Março | D17: 45719 | E17: =TODAY() -> 46171 | F17: =DATEDIF(Tabela153[[#This Row],[Data entrada]],Tabela153[[#This Row],[Data 2]], "M") -> 14 | G17: Sérgio | H17: 1900 | I17: 0.05 | K17: Active | M17: =COUNTIFS('Reuniões 2025'!I:I, B17) -> 52 | Y17: =COUNTIFS('Reuniões 2025'!I:I, B17) -> 52
B18: Qucaan | C18: 2025 Março | D18: 45721 | E18: =TODAY() -> 46171 | F18: =DATEDIF(Tabela153[[#This Row],[Data entrada]],Tabela153[[#This Row],[Data 2]], "M") -> 14 | G18: Sérgio | H18: 1500 | K18: Active | M18: =COUNTIFS('Reuniões 2025'!I:I, B18) -> 18 | Y18: =COUNTIFS('Reuniões 2025'!I:I, B18) -> 18
B19: Texteis Penedo | C19: 2025 Março | D19: 45729 | E19: =TODAY() -> 46171 | F19: =DATEDIF(Tabela153[[#This Row],[Data entrada]],Tabela153[[#This Row],[Data 2]], "M") -> 14 | G19: Sofia | H19: 1900 | I19: 0.05 | K19: Active | M19: =COUNTIFS('Reuniões 2025'!I:I, B19) -> 0 | Y19: =COUNTIFS('Reuniões 2025'!I:I, B19) -> 0
B20: Aronlight | C20: 2025 Março | D20: 45720 | E20: =TODAY() -> 46171 | F20: =DATEDIF(Tabela153[[#This Row],[Data entrada]],Tabela153[[#This Row],[Data 2]], "M") -> 14 | G20: Allen | H20: 1300 | I20: 0.065 | K20: Active | M20: =COUNTIFS('Reuniões 2025'!I:I, B20) -> 18 | Y20: =COUNTIFS('Reuniões 2025'!I:I, B20) -> 18
B21: Acushla | C21: 2025 Abril | D21: 45754 | E21: =TODAY() -> 46171 | F21: =DATEDIF(Tabela153[[#This Row],[Data entrada]],Tabela153[[#This Row],[Data 2]], "M") -> 13 | G21: Allen | H21: 1250 | I21: 0.05 | K21: active | M21: =COUNTIFS('Reuniões 2025'!I:I, B21) -> 18 | Y21: =COUNTIFS('Reuniões 2025'!I:I, B21) -> 18
B22: Tetribérica | C22: 2025 Abril | D22: 45754 | E22: =TODAY() -> 46171 | F22: =DATEDIF(Tabela153[[#This Row],[Data entrada]],Tabela153[[#This Row],[Data 2]], "M") -> 13 | G22: Sofia | H22: 1250 | I22: 0.05 | K22: Active | M22: =COUNTIFS('Reuniões 2025'!I:I, B22) -> 17 | Y22: =COUNTIFS('Reuniões 2025'!I:I, B22) -> 17
B23: Genan, S.A. | C23: 2025 Abril | D23: 45751 | E23: =TODAY() -> 46171 | F23: =DATEDIF(Tabela153[[#This Row],[Data entrada]],Tabela153[[#This Row],[Data 2]], "M") -> 13 | G23: Sérgio | H23: 1900 | I23: 0.05 | K23: active | M23: =COUNTIFS('Reuniões 2025'!I:I, B23) -> 0 | Y23: =COUNTIFS('Reuniões 2025'!I:I, B23) -> 0
B24: Ricarle Stone | C24: 2025 Abril | D24: 45751 | E24: =TODAY() -> 46171 | F24: =DATEDIF(Tabela153[[#This Row],[Data entrada]],Tabela153[[#This Row],[Data 2]], "M") -> 13 | G24: Sérgio | H24: 1500 | I24: 0.05 | K24: Active | M24: =COUNTIFS('Reuniões 2025'!I:I, B24) -> 33 | Y24: =COUNTIFS('Reuniões 2025'!I:I, B24) -> 33
B25: OneOutfit | C25: 2025 Abril | D25: 45776 | E25: =TODAY() -> 46171 | G25: Sofia | H25: 1000 | I25: 0.03 | M25: =COUNTIFS('Reuniões 2025'!I:I, B25) -> 3 | Y25: =COUNTIFS('Reuniões 2025'!I:I, B25) -> 3
B26: Termopainel | C26: 2025 Abril | D26: 45763 | E26: =TODAY() -> 46171 | G26: Sofia | H26: 1600 | I26: 0.01 | M26: =COUNTIFS('Reuniões 2025'!I:I, B26) -> 36 | Y26: =COUNTIFS('Reuniões 2025'!I:I, B26) -> 36
B27: Têxtil Nortenha | C27: 2025 Abril | D27: 45763 | E27: =TODAY() -> 46171 | G27: Sofia | H27: 1500 | I27: 0.05 | M27: =COUNTIFS('Reuniões 2025'!I:I, B27) -> 7 | Y27: =COUNTIFS('Reuniões 2025'!I:I, B27) -> 7
B28: Biocheers | C28: 2025 Maio | D28: 45789 | E28: =TODAY() -> 46171 | F28: =DATEDIF(Tabela153[[#This Row],[Data entrada]],Tabela153[[#This Row],[Data 2]], "M") -> 12 | G28: Allen | H28: 1500 | I28: 0.05 | M28: =COUNTIFS('Reuniões 2025'!I:I, B28) -> 10 | Y28: =COUNTIFS('Reuniões 2025'!I:I, B28) -> 10
B29: Santa Marta | C29: 2025 Maio | D29: 45792 | E29: =TODAY() -> 46171 | F29: =DATEDIF(Tabela153[[#This Row],[Data entrada]],Tabela153[[#This Row],[Data 2]], "M") -> 12 | G29: Sofia | H29: 1500 | I29: 0.05 | M29: =COUNTIFS('Reuniões 2025'!I:I, B29) -> 1 | Y29: =COUNTIFS('Reuniões 2025'!I:I, B29) -> 1
B30: wTVision | C30: 2025 Junho | D30: 45811 | E30: =TODAY() -> 46171 | G30: Manuel | H30: 1900 | I30: 0.05 | M30: =COUNTIFS('Reuniões 2025'!I:I, B30) -> 9 | Y30: =COUNTIFS('Reuniões 2025'!I:I, B30) -> 9
B31: Drops Nazaré | C31: 2025 Junho | D31: 45825 | E31: =TODAY() -> 46171 | G31: Sofia | H31: 1500 | I31: 0.05 | M31: =COUNTIFS('Reuniões 2025'!I:I, B31) -> 14 | Y31: =COUNTIFS('Reuniões 2025'!I:I, B31) -> 14
B32: Residence | C32: 2025 Julho | D32: 45840 | E32: =TODAY() -> 46171 | G32: Allen | H32: 1500 | I32: 0.05 | M32: =COUNTIFS('Reuniões 2025'!I:I, B32) -> 9 | Y32: =COUNTIFS('Reuniões 2025'!I:I, B32) -> 9
B33: Happy Probability | C33: 2025 Julho | D33: 45841 | E33: =TODAY() -> 46171 | G33: Sofia | H33: 1500 | I33: 0.05 | M33: =COUNTIFS('Reuniões 2025'!I:I, B33) -> 9 | Y33: =COUNTIFS('Reuniões 2025'!I:I, B33) -> 9
E34: =TODAY() -> 46171 | F34: =DATEDIF(Tabela153[[#This Row],[Data entrada]],Tabela153[[#This Row],[Data 2]], "M") -> 1516
B35: Exposerve | C35: 2025 Janeiro | D35: 45659 | E35: 45754 | F35: =DATEDIF(Tabela153[[#This Row],[Data entrada]],Tabela153[[#This Row],[Data 2]], "M") -> 3 | G35: Sérgio | H35: 1500 | J35: 3 | K35: hold
B36: Ramagplast | C36: 45658 | D36: 45665 | E36: 45747 | F36: =DATEDIF(Tabela153[[#This Row],[Data entrada]],Tabela153[[#This Row],[Data 2]], "M") -> 2 | G36: Sérgio | H36: 1000 | J36: 1 | K36: hold
B37: José Luis Madeiras | C37: 45597 | D37: 45616 | E37: 45708 | F37: =DATEDIF(Tabela153[[#This Row],[Data entrada]],Tabela153[[#This Row],[Data 2]], "M") -> 3 | G37: Sérgio | H37: 1500 | I37: - | J37: 1 | K37: hold
B38: Farvoli | C38: 45444 | D38: 45454 | E38: 45576 | F38: =DATEDIF(Tabela153[[#This Row],[Data entrada]],Tabela153[[#This Row],[Data 2]], "M") -> 4 | G38: Marco | H38: 1500 | I38: - | J38: 2 | K38: hold
B39: Arxi | C39: 45559 | D39: 45537 | E39: 45567 | F39: =DATEDIF(Tabela153[[#This Row],[Data entrada]],Tabela153[[#This Row],[Data 2]], "M") -> 1 | G39: Marco | H39: 1500 | I39: - | J39: 1 | K39: hold
B40: Atelier Sabiina Design | C40: dec/2024 | D40: 45627 | E40: 45627 | F40: =DATEDIF(Tabela153[[#This Row],[Data entrada]],Tabela153[[#This Row],[Data 2]], "M") -> 0 | G40: Sérgio | H40: 1500 | J40: 1 | K40: hold
B41: GinT | C41: 45474 | D41: 45482 | E41: 45544 | F41: =DATEDIF(Tabela153[[#This Row],[Data entrada]],Tabela153[[#This Row],[Data 2]], "M") -> 2 | G41: Allen | H41: 1500 | I41: - | J41: 3 | K41: hold | L41: estamos à espera do pagamento para continuar
B42: Mariano | C42: 45505 | D42: 45505 | E42: 45413 | G42: Isabela | H42: 800 | J42: 0 | K42: hold | L42: quer renovar, ainda n deu data
B43: Artemola | C43: 45078 | D43: 45444 | E43: 45544 | G43: Allen | H43: 1100 | J43: 15 | K43: hold | L43: volta em fevereiro
B44: Jossois | C44: 45597 | D44: 45617 | E44: 45737 | F44: =DATEDIF(Tabela153[[#This Row],[Data entrada]],Tabela153[[#This Row],[Data 2]], "M") -> 4 | G44: Manel | H44: 1200 | I44: - | J44: 1 | K44: hold
...

Sheet Reuniões 2025
G1: Account Manager | H1: País | I1: Cliente | J1: Potencial Cliente | K1: Data | L1: Score
G2: Allen | H2: MA | I2: Arte&Mola | J2: Extra Matelas | K2: 27/05/2024
G3: Allen | H3: MA | I3: Techno Store | J3: YEP | K3: 45419
G4: Allen | H4: TU | I4: Arte&Mola | J4: Materna | K4: 45572
G5: Allen | H5: MA | I5: Techno Store | J5: Yaratech | K5: 17/07/2024
G6: Vânia | H6: KW | I6: New Mattress | J6: La Casa | K6: 24/07/2024
G7: Vânia | H7: UAE | I7: Farimovel | J7: Magna General Trading | K7: 24/07/2024
G8: Allen | H8: LI | I8: Gin T | J8: Abi Ramia Bros | K8: 25/07/2024
G9: Allen | H9: AL | I9: Arte&Mola | J9: La Belle Literie | K9: 25/07/2024
G10: Vânia | H10: QA | I10: Farimovel | J10: Fab Furnish | K10: 26/07/2024
G11: Marco | H11: LI | I11: Delta | J11: Malia Group | K11: 29/07/2024
G12: Vânia | H12: UAE | I12: New Mattress | J12: Bafte | K12: 29/07/2024
G13: Isabela | H13: UAE | I13: FM Têxteis | J13: Jokes Aside | K13: 30/07/2024
G14: Allen | H14: LI | I14: Gin T | J14: Barlivery | K14: 31/07/2024
G16: Marco | H16: UAE | I16: Granidense | J16: Emirates Marble & Granite | K16: 45299
G17: Marco | H17: UAE | I17: Artnovion | J17: Bishop Design | K17: 45330
G18: Marco | H18: TU | I18: Vittawood | J18: General Distribuition Placo | K18: 45330
G19: Marco | H19: UAE | I19: Delta | J19: Al Abdullah Group | K19: 45420
G20: Isabela | H20: UAE | I20: Gema | J20: Sand Circus | K20: 45451
G21: Marco | H21: SA | I21: Granidense | J21: Al-Rahmani Group | K21: 45451
G22: Allen | H22: LI | I22: Gin T | J22: Dekkeni | K22: 45481
G23: Isabela | H23: SA | I23: FM Têxteis | J23: One of a Kind | K23: 45512
G24: Vânia | H24: MA | I24: New Mattress | J24: Mon Mantelas | K24: 45634
G25: Vânia | H25: SA | I25: Farimovel | J25: Majed Harasani Design | K25: 13/8/2024
G26: Marco | H26: UAE | I26: Recheio | J26: FJX | K26: 28/08/2024
G28: Allen | H28: LI | I28: Gin T | J28: Abi Ramia Bros | K28: 45331
G29: Marco | H29: SA | I29: Arxi | J29: NSK Consulting | K29: 45537
G30: Marco | H30: UAE | I30: Artnovion | J30: DZ Design | K30: 45538
G31: Allen | H31: TU | I31: Techno Store | J31: Ranim Distribution | K31: 45574
G32: Marco | H32: SA | I32: Vittawood | J32: STQ Group | K32: 45545
G33: Marco | H33: SA | I33: Arxi | J33: Agap2IT | K33: 45547
G34: Marco | H34: SA | I34: Granidense | J34: NBR Centre | K34: 45548
G35: Allen | H35: UAE | I35: Gin T | J35: Centaurus | K35: 17/09/2024
G36: Allen | H36: MA | I36: Arte&Mola | J36: Arton Confort | K36: 19/09/2024
G37: Marco | H37: QA | I37: Delta | J37: Al Maya | K37: 45554
G38: Marco | H38: EG | I38: Vittawood | J38: Egyptian Supplies | K38: 45537
G39: Allen | H39: MA | I39: Gin T | J39: Bourchanin&Cie | K39: 26/09/2024
G40: Marco | H40: TU | I40: Farvoli | J40: ITAK | K40: 45301
G41: Allen | H41: TU | I41: Techno Store | J41: Tunewtech | K41: 45332
G42: Allen | H42: LI | I42: Gin T | J42: Ziad Chanine | K42: 45392
...

Sheet Reuniões 2026
A1: Account Manager | B1: País | C1: Cliente | D1: Potencial Cliente | E1: Data | F1: Score
A2: WEEK 1 | B2: WEEK 1 | C2: WEEK 1 | D2: WEEK 1 | E2: WEEK 1 | F2: WEEK 1
A3: Maiza/Allen/Pedro | B3: Reunião de Alinhamento | C3: Bocean | D3: MAAB | E3: 46024
A4: WEEK 2 | B4: WEEK 2 | C4: WEEK 2 | D4: WEEK 2 | E4: WEEK 2 | F4: WEEK 2
A5: Allen | B5: UAE | C5: Alpine Seafood | D5: Chef Middle East | E5: 46027 | F5: 4
A6: Julia | B6: SA | C6: Sweet and Sugar | D6: Balsharaf Group | E6: 46143 | F6: N/A
A7: Julia | B7: SA | C7: Yogoody | D7: Nutrition Diet Center | E7: 46143 | F7: N/A
A8: Maíza | B8: EG | C8: Altix | D8: MAM Electric | E8: 46143 | F8: 4
A9: Allen | B9: UAE | C9: Artnovion | D9: Salt Technology Services | E9: 46174 | F9: 4
A10: Allen | B10: UAE | C10: Districaia | D10: Joud Coffee | E10: 46174 | F10: 4
A11: Julia | B11: SA | C11: Yogoody | D11: Almunajem | E11: 46174 | F11: 4
A12: Allen | B12: KW | C12: Emotional Brands | D12: Inside Design Company | E12: 46028 | F12: 4
A13: Allen | B13: UAE | C13: Sutol | D13: Dennemeyer | E13: 46204 | F13: 1
A14: Allen | B14: QA | C14: Emotional Brands | D14: Al Jameel Showroom | E14: 46030 | F14: 4
A15: Allen | B15: KW | C15: Delta Cafés | D15: Kuwait Proteins | E15: 46235 | F15: 3
A16: David | B16: SN | C16: Genan | D16: MangoSports | E16: 46235 | F16: 3
A17: Julia | B17: GH | C17: Yogoody | D17: Rafimex | E17: 46266 | F17: 4
A18: Ana | B18: Reunião Status | C18: Core Cocept | D18: MAAB | E18: 46030
A19: Ana | B19: Reunião Status | C19: Fernandes e Sampaio | D19: MAAB | E19: 46030
A20: Ana /Maiza | B20: Reunião de Projeto | C20: Altix | D20: MAAB | E20: 46030
A21: Ana | B21: Reunião Status | C21: Coltec | D21: MAAB | E21: 46030
A22: Ana | B22: Reunião Status | C22: Yogoody | D22: MAAB | E22: 46030
A23: Ana | B23: Reunião Status | C23: ALTIX | D23: MAAB | E23: 46029
A24: Maiza/Ana | B24: Reunião AlInhamento | C24: Animovel | D24: MAAB | E24: 46028
A25: Allen/João/Pedro/Ana | B25: Reunião de Projeto | C25: Freshland | D25: MAAB | E25: 46027
A26: Ana/Julia | B26: Reunião de Projeto | C26: SONATURAL | D26: MAAB | E26: 46027
A27: WEEK 3 | B27: WEEK 3 | C27: WEEK 3 | D27: WEEK 3 | E27: WEEK 3 | F27: WEEK 3
A28: Julia | B28: UAE | C28: Fernandes e Sampaio | D28: UNLO | E28: 46357 | F28: N/A
A29: Julia | B29: SA | C29: SONATURAL | D29: Rawasi Group | E29: 46357 | F29: 3
A30: David | B30: QA | C30: Artnovion | D30: Execute Interiors | E30: 13/1/2026 | F30: 3
A31: David | B31: BR | C31: Core Concept | D31: PSA Arquitetura | E31: 13/1/2026 | F31: N/A
A32: Julia | B32: UAE | C32: Districaia | D32: DP World | E32: 13/1/2026 | F32: N/A
A33: Julia | B33: QA | C33: Delta Cafés | D33: Ali Bin Ali | E33: 13/1/2026 | F33: 3
A34: Maíza | B34: EG | C34: Altix | D34: ANNCO | E34: 13/1/2026 | F34: 4
A35: Maíza | B35: KSA | C35: Aquecinox | D35: Pure Seasons | E35: 13/1/2026 | F35: N/A
A36: David | B36: MA | C36: Denodl | D36: CP Tech | E36: 14/1/2026 | F36: N/A
A37: David | B37: MA | C37: Denodl | D37: IrriPower | E37: 14/1/2026 | F37: 3
A38: Julia | B38: UAE | C38: Alpine Seafood | D38: Organic Food & Cafe | E38: 14/1/2026 | F38: N/A
A39: David | B39: UAE | C39: Artnovion | D39: Focus Acoustics | E39: 15/1/2026 | F39: 3
A40: David | B40: UAE | C40: Artnovion | D40: Design Young | E40: 15/1/2026 | F40: 4
...

Sheet Pagamentos
A1: Nome | B1: Inicio | C1: Dia começo | D1: Monthly Fee | E1: Success Fee | F1: Setembro | G1: Setembro | H1: Outubro | I1: Novembro | J1: Dezembro | K1: Enero | L1: Febrero | M1: Marzo | N1: Abril | O1: Mayo | P1: Junio
A2: Delta | B2: 45444 | C2: 1 de junho | D2: 1100 | E2: -
A3: GinT | B3: 45474 | C3: 9 de julho | D3: 1500 | E3: -
A4: Givachoice | B4: 45444 | C4: 27 de junho | D4: 2.400 € | E4: -
A5: Aquecinox | B5: 45690 | C5: 5 de fevereiro | D5: 1500
A6: Core Concept | B6: 45718 | C6: 3 de março | D6: 1900 | E6: 0.05
A7: Genan | B7: 45748 | C7: 4 de abril | D7: 1900 | E7: 0.05
A8: Freshland Harvest | B8: 45778 | C8: 12 de maio | D8: 1500 | E8: 0.05
A9: Happy Probability | B9: 45839 | C9: 3 de julho | D9: 1300 | E9: 0.05
A10: Garsteel | B10: 45839 | C10: 14 de julho | D10: 1900 | E10: 0.03
A11: Sutol | B11: 45839 | C11: 7 de julho | D11: 1900 | E11: 0.03
A12: Compincar | B12: 45901 | C12: 1 de setembro | D12: 1500
A13: Altix | B13: 45901 | C13: 1 de setembro | D13: 1200 | E13: 0.06
A14: Districaia | B14: 45931 | C14: 8 de outubro | D14: 1500 | E14: 0.05
A15: NCFHK | B15: 45931 | C15: 3 de novembro | D15: 1500 | E15: 0.05
A16: GL | B16: 45992 | C16: 30 de dezembro | D16: 1200 | E16: 0.05
A17: Denodl | B17: 46023 | C17: 5 de janeiro | D17: 2.100 €
A18: Animovel | B18: 46023 | C18: 6 de janeiro | D18: 1750 | E18: 0.05
A19: PHF | B19: 46023 | C19: 23 de janeiro | D19: 1500 | E19: 0.05
A20: Frutorra | B20: 46023 | C20: 28 de janeiro | D20: 1300 | E20: 0.02
A21: Innatam | B21: 46054 | C21: 2 de fevereiro | D21: 1500 | E21: 0.05
A22: Pavinorte | B22: 46056 | C22: 18 de fevereiro | D22: 1900 | E22: 0.05
A23: Madeivouga | B23: 46056 | C23: 18 de fevereiro | D23: 1900 | E23: 0.05
A24: Sagiper | B24: 46084 | C24: 4 de março | D24: 1750 | E24: 0.05
A25: Topeca | B25: 46084 | C25: 5 de março | D25: 1750 | E25: 0.05
A26: Urbiagua | B26: 46084 | C26: 17 de março | D26: 1300 | E26: 0.05
A27: Ibernop | B27: 46083 | C27: 27 de março | D27: 1750 | E27: 0.05
A28: Atlantic Wood | B28: 46083 | C28: 31 de março | D28: 1900 | E28: 0.05
A29: Magic Way | B29: 46083 | C29: 31 de março | D29: 750 | E29: 0.05
... A33: Conformetal | B33: 46143 | C33: 1 de maio | D33: 1500 | E33: 0.05
A34: Tecnifreza | B34: 46143 | C34: 1 de maio | D34: 1250 | E34: 2% - 4%
A35: Grupo Eleva | B35: 46143 | C35: 1 de maio | D35: 500
A36: PTGAL Business | B36: 46143 | C36: 26 de maio | D36: 1500 | E36: 0.02
A37: Helitene | B37: 46174 | C37: 1 de junho | D37: 1750 | E37: 0.02
A38: Carldora | B38: 46174 | C38: 1 de junho | D38: 1500 | E38: 0.02
A39: Umbelino Monteiro | B39: 46023 | C39: 23 de janeiro | D39: 1500
